Workbook

Sheet Varietal
A1: Varietal | B1: Text | C1: Category | D1: text lenght max(300) | E1: Tane
A2: Red Bourbon | B2: This microlot is 100% Bourbon. This varietal is a natural mutation of the Coffee Arabigo. The name Bourbon was given after an island now called Reunion, off the coast of Madagascar. | C2: Exotic | D2: =+LEN(B2) -> 181 | E2: Finalised
A3: Bourbon Aruzi | B3: This variety was discovered in Inza, Cauca when a coffee tree was found to look very different from the typical coffee grown in the region. This unknown variety had a higher yield and was more resistant. As a result, some farmers began to grow this variety. Subsequently, the seeds were studied by a laboratory in London which found that the genetics and structure were similar to Bourbon Aruzi, a variety grown in Ethiopia | C3: Exotic | D3: =+LEN(B3) -> 423
A4: Bourbon Primitivo | B4: This varietal was planted by Luis Anibal Calderon in 2017. He came across a Bourbon tree with a distinct appearance and made the decision to take the seeds and plant additional trees of this variety. As he had discovered this unique coffee, he chose to give it a new name that would set it apart from the regular Bourbon variety. Thus, he named it Bourbon Primitivo. | C4: Exotic | D4: =+LEN(B4) -> 367 | E4: Finalised
A5: Castillo | B5: This microlot is 100% Castillo. This variety was developed by Federación Nacional de Cafeteros. It is more productive than Caturra and resistant to coffee leaf rust. | C5: Microlot | D5: =+LEN(B5) -> 165 | E5: Finalised
A6: Catimor | B6: This microlot is 100% Catimor (Costa Rica 95). This varietal is leaf rust resistant and was developed by “The Costa Rica Coffee Institute”. Costa 95 is a cross between Timor Hybrid and Caturra. | C6: Microlot | D6: =+LEN(B6) -> 193 | E6: Finalised
A7: Catuai | B7: A cross between Mundo Novo and compact Caturra, made by the Instituto Agronomico (IAC) of Sao Paulo State in Campinas, Brazil. | C7: Exotic | D7: =+LEN(B7) -> 128 | E7: Finalised
A8: Caturra | B8: This microlot is 100% Caturra. This variety originated in Minas Gerais, Brazil. It is a natural mutation of Red Bourbon. Caturra produces more coffee and is more resistant to plant diseases than Bourbon. | C8: Microlot | D8: =+LEN(B8) -> 203 | E8: Finalised
A9: Caturron | B9: This microlot is 100% Caturron. This varietal is a rare mutation of Caturra found for the first time in Acevedo, Huila. Growers started planting Caturron due to its resistance to leaf rust and high yield. But it wasn't until 2016 when Cofinet, with the help of some growers from the region, identified the exotic cup profile of this varietal. | C9: Exotic | D9: =+LEN(B9) -> 342 | E9: Finalised
A10: Cenicafe 1 | B10: Cenicafé 1 is a new variety of coffee tree developed by the Colombian Coffee Research Center (Cenicafé). It is a hybrid of the Caturra and Castillo varieties. It is disease-resistant and has a good yield. It has a balanced flavor of sweetness and acidity, with chocolate and citrus notes. | C10: Microlot | D10: =+LEN(B10) -> 288 | E10: Finalised
A11: Chilli Bourbon | B11: This microlot is 100% Chilli Bourbon. This varietal is rare mutation that took place in Acevedo, Huila. The name of this variety came after the pickers who tried it first discovered the cherry had a taste with a hint of spicy similar to chili. | C11: Exotic | D11: =+LEN(B11) -> 243 | E11: Finalised
A12: Chiroso Bourbon | B12: This microlot is 100% Chiroso. This varietal is a natural mutation that took place in Urrao, Antioquia. For the last 5 years, this varietal has become extremely popular in Colombia for its complexity, florals, and citrus notes. | C12: Exotic | D12: =+LEN(B12) -> 227 | E12: Finalised
A13: Costa Rica | B13: This microlot is 100% Costa Rica 95. | C13: Microlot | D13: =+LEN(B13) -> 36 | E13: Finalised
A14: Gesha | B14: This microlot is 100% Gesha. This varietal was first discovered in Abyssinia, Ethiopia in 1931. Gesha was planted in Panama for the first time in 1963 and in Colombia in 2005. | C14: Microlot | D14: =+LEN(B14) -> 175 | E14: Finalised
A15: Red Gesha | B15: This microlot is 100% Gesha. This varietal was first discovered in Abyssinia, Ethiopia in 1931. Gesha was planted in Panama for the first time in 1963 and in Colombia in 2005. | C15: Exotic | D15: =+LEN(B15) -> 175 | E15: Finalised
A16: Gesha King | B16: This particular varietal was planted by Luis Anibal Calderon in 2017. Within his crop of Gesha coffee, he stumbled upon a Gesha tree that produced coffee cherries noticeably larger in size compared to the typical ones found in Gesha trees. To distinguish this newly discovered variation from the traditional Gesha, Luis Anibal named it "Gesha King." | C16: Exotic | D16: =+LEN(B16) -> 349
A17: Java | B17: This micro-lot is 100% Java. This variety originated in Ethiopia and is a natural mutation of Typica. The seeds were taken to Indonesia where it was named Java. In 1991, it was introduced to Costa Rica and in 2010, it made its way into Colombia. | C17: Exotic | D17: =+LEN(B17) -> 245 | E17: Finalised
A18: Maracatura | B18: This microlot is 100% Maracaturra. This variety is a cross between Maragogype and Caturra. This variety is common in Nicaragua but very hard to find in Colombia. | C18: Exotic | D18: =+LEN(B18) -> 161 | E18: Finalised
A19: Maragesha | B19: This microlot is 100% Maragesha. This varietal is a natural cross between the Gesha and Maragogype varietals that took place at Luis Anibal’s farm, Finca Villa Betulia, in 2017. | C19: Exotic | D19: =+LEN(B19) -> 177 | E19: Finalised
A20: Maragogype | B20: This microlot is 100% Maragogype. | C20: Exotic | D20: =+LEN(B20) -> 33 | E20: Finalised
A21: Mokka | B21: This microlot is 100% Mokka. This variety originated in Yemen. It is named after the city Mocca in Yemen located right next to the red sea. This variety is known for producing beans much smaller than usual and its distinctive taste (very aromatic and full bodied). | C21: Exotic | D21: =+LEN(B21) -> 264 | E21: Finalised
A22: Ethiopian Heirloom | B22: This variety is native to Ethiopia and many years ago seeds arrived in Huila. Luis was the lucky one who was able to cultivate and understand the behavior of this plant. The results after many years of monitoring and experimenting are interesting. The cherry is elongated and has a belly button shape on the base of the fruit. | C22: Exotic | D22: =+LEN(B22) -> 327
A23: Yellow Pacamara | B23: The Yellow Pacamara is a natural mutation of the Red Pacamara (a cross between a Maragogype and Pacas). It was discovered by the Mierisch Family in Nicaragua. Yellow Pacamara cherries are similar to the more common Pacamara variety. | C23: Exotic
A24: Pacamara | B24: This microlot is 100% Pacamara. It is a variety created in El Salvador. It is a cross between Pacas and Maragogipe. This variety is low yield, however, has an exceptional cup profile. | C24: Exotic | D24: =+LEN(B24) -> 184 | E24: Finalised
A25: Papayo | B25: This microlot is 100% Papayo. This varietal is a rare mutation that took place in Acevedo, Huila. Ripe cherries turn orange in colour and the shape is similar to a papaya. The cup profile is complex with defined jasmine, sugar cane, and sweet chocolate notes. | C25: Exotic | D25: =+LEN(B25) -> 259 | E25: Finalised
A26: Pink Gesha | B26: This variety of Gesha originated from a mutation that occurred on a farm in Huila, where over time, some of the fruits began to ripen to a pinkish hue. Despite their different color, the cup profile was the same as the traditional red Gesha. We decided to selectively harvest the pink cherries and use their seeds to cultivate this Pink Gesha in Jardines del Eden. The resulting cup profile is just as exceptional as that of the red Gesha. | D26: =+LEN(B26) -> 439 | E26: Finalised
A27: Pink Bourbon | B27: This micro-lot is 100% Pink Bourbon. This varietal is currently under research in order to determine its origin. It is said that it is a mutation that took place at 2100 m.a.s.l in San Adolfo, Huila. | C27: Exotic | D27: =+LEN(B27) -> 199 | E27: Finalised
A28: Purple Bourbon | B28: This microlot is 100% Purple Bourbon. This variety is a mutation of Bourbon although the cherries ripen to be purple and the cup profile is more floral than Bourbon. | C28: Exotic | D28: =+LEN(B28) -> 165 | E28: Finalised
A29: Red Caturra | B29: This variety originated in Minas Gerais, Brazil. It is a natural mutation of Red Bourbon. Caturra produces more coffee and is more resistant to plant diseases than Bourbon. | C29: Exotic | D29: =+LEN(B29) -> 172 | E29: Finalised
A30: San Bernardo | B30: San Bernardo varietal is a natural mutation of Typica originated in Guatemala. It is a very rare varietal to come across in Colombia. Trees are even smaller than Caturra or Castillo and not resistant to leaf rust. The yield is low, and the cup profile is quite unique, complex with floral notes, spices, and a medium body. | C30: Exotic | D30: =+LEN(B30) -> 322 | E30: Finalised
A31: Sidra Bourbon | B31: Sidra is a hybrid between Bourbon and Typica varieties. Its sweet and bright profile is a characteristic of this unique variety, said to have originated in Ecuador. Sidra's height is medium, the yield is high, all the cherries ripen to be red, and the trees are tolerant to leaf rust and drought but are susceptible to pests. | C31: Exotic | D31: =+LEN(B31) -> 326 | E31: Finalised
A32: SL - 28 | B32: This microlot is 100% SL28. This varietal was developed by Scott Laboratories to suit Kenya soils and climate conditions in 1931. This varietal is very scarce in Colombia. | C32: Exotic | D32: =+LEN(B32) -> 171 | E32: Finalised
A33: Striped Bourbon | B33: A natural mutation of Bourbon, this unique variety was discovered in the municipality of San Adolfo in Huila. It features distinctive vertical stripes on its cherry. It is susceptible to leaf rust and yields low production. However, its cup profile is exceptionally complex, with a delightful blend of sweetness and floral notes. | C33: Exotic | D33: =+LEN(B33) -> 329 | E33: Finalised
A34: Tabi | B34: This micro-lot is 100% Tabi. This is a new variety developed by “Federacion Nacional de Cafeteros.” This unique variety is a cross between the Timor Hybrid, Bourbon, and Typica. | C34: Microlot | D34: =+LEN(B34) -> 177 | E34: Finalised
A35: Typica Mejorado | B35: This micro-lot is 100% Typica Mejorado. This varietal was developed in an experimental center in Ecuador. This coffee is rust-resistant, has good yield potential, and has a very good cup profile. | C35: Microlot | D35: =+LEN(B35) -> 197
A36: Pink Typica | B36: This is a traditional variety in Colombia and most of the small-scale coffee farmers have this variety in their parcels. Until the 1940s, the majority of coffee plantations in South and Central America were planted with Typica.Very few plantations produce ripe, pink-colored fruit, which makes this lot a unique selection. | C36: Microlot | D36: =+LEN(B36) -> 322
A37: Typica | B37: This is a traditional variety in Colombia and most of the small-scale coffee farmers have this variety in their parcels. In the late eighteenth century, cultivation spread to the Caribbean, Mexico, and Colombia. Until the 1940s, the majority of coffee plantations in South and Central America were planted with Typica. | C37: Microlot | D37: =+LEN(B37) -> 319 | E37: Finalised
A38: Variedad Colombia | B38: This microlot is 100% Variedad Colombia. This variety was developed by the Colombian Coffee Federation in order to fight leaf rust and is a hybridization of Caturra and Timor Hybrid. | C38: Microlot | D38: =+LEN(B38) -> 182 | E38: Finalised
A39: Wush Wush | B39: This microlot is 100% Wush Wush. This is a rare varietal grown in Colombia. It is believed that it made its way from Ethiopia about 25 years ago from Wush Wush. The cup profile is very floral, tea-like, and very complex. | C39: Exotic | D39: =+LEN(B39) -> 220 | E39: Finalised
A40: Yellow Bourbon | B40: This microlot is 100% Yellow Bourbon. This varietal is a natural mutation of the Coffee Arabigo. The name Bourbon was given after an island now called Reunion, off the coast of Madagascar. | C40: Exotic | D40: =+LEN(B40) -> 188 | E40: Finalised
...

Sheet Process
A1: Process | B1: Text | C1: text_lenght (max 330) | E1: Tane
A2: Decaf | B2: This decaffeination process is unique. The caffeine is extracted from the bean using sugar cane ethyl acetate (EA) and water which enhances sweetness while maintaining coffee attributes. | C2: =+LEN(B2) -> 186 | E2: Finalised
A3: Natural Decaf | B3: This coffee was carefully hand-picked in order to select only the ripest cherries and then hand sorted to remove any defects. The coffee was sundried on raised beds in temperature-controlled conditions until the ideal moisture content is achieved. This decaffeination process is unique. The caffeine is extracted from the bean using sugar cane ethyl acetate (EA) and water which enhances sweetness while maintaining coffee attributes. | C3: =+LEN(B3) -> 434
A4: Honey | B4: Cherries for this microlot were picked following strict ripeness criteria. Cherries were later pulped and exposed to 35 hours of dry fermentation. Later, the cherries were placed on raised beds for 11 days until 10% moisture content was reached. | C4: =+LEN(B4) -> 245 | E4: Finalised
A5: Honey - Peru | B5: Cherries were later pulped and exposed to 35 hours of dry fermentation. The cherries were then placed on raised beds for 11 days until 10% moisture content was reached. | C5: =+LEN(B5) -> 168 | E5: Finalised
A6: Honey + (Tartaric Acid / Banana) | B6: This coffee was exposed to a dry anaerobic fermentation period of 72 hours with the pulp on. During this fermentation stage, banana and tartaric acid were added. The cherries were then pulped and placed to dry on raised beds until ideal moisture content was achieved. | C6: =+LEN(B6) -> 267
A7: Honey + (Tartaric Acid / Lulo) | B7: This coffee was exposed to a dry anaerobic fermentation period of 72 hours with the pulp on. During this fermentation stage, lulo and tartaric acid were added. The cherries were then pulped and placed to dry on raised beds until ideal moisture content was achieved. | C7: =+LEN(B7) -> 265
A8: Honey + (Tartaric Acid/ Strawberry) | B8: This coffee was exposed to a dry anaerobic fermentation period of 72 hours with the pulp on. During this fermentation stage, strawberry and tartaric acid were added. The cherries were then pulped and placed to dry on raised beds until ideal moisture content was achieved. | C8: =+LEN(B8) -> 271
A9: Honey + ( Tartaric Acid / Lychee) | B9: This coffee was exposed to a dry anaerobic fermentation period of 72 hours with the pulp on. During this fermentation stage, lychee and tartaric acid were added. The cherries were then pulped and placed to dry on raised beds until ideal moisture content was achieved. | C9: =+LEN(B9) -> 267
A10: Honey + ( Tartaric Acid / Peach) | B10: This coffee was exposed to a dry anaerobic fermentation period of 72 hours with the pulp on. During this fermentation stage, peach and tartaric acid were added. The cherries were then pulped and placed to dry on raised beds until ideal moisture content was achieved. | C10: =+LEN(B10) -> 266
A11: Honey + ( Tartaric Acid / Passion Fruit) | B11: This coffee was exposed to a dry anaerobic fermentation period of 72 hours with the pulp on. During this fermentation stage, passion fruit pulp and tartaric acid were added. The cherries were then pulped and placed to dry on raised beds until ideal moisture content was achieved. | C11: =+LEN(B11) -> 279
A12: Honey + ( Tartaric Acid / Cinnamon) | B12: This coffee was exposed to a dry anaerobic fermentation period of 72 hours with the pulp on. During this fermentation stage, cinnamon sticks and tartaric acid were added. The cherries were then pulped and placed to dry on raised beds until ideal moisture content was achieved. | C12: =+LEN(B12) -> 276
A13: Honey + ( Tartaric Acid / Eucalyptus) | B13: This coffee was exposed to a dry anaerobic fermentation period of 72 hours with the pulp on. During this fermentation stage, dried eucalyptus leaves and tartaric acid were added. The cherries were then pulped and placed to dry on raised beds until ideal moisture content was achieved. | C13: =+LEN(B13) -> 284 | E13: Finalised
A14: Honey + (Tartaric Acid / Lemongrass) | B14: This coffee was exposed to a dry anaerobic fermentation period of 72 hours with the pulp on. During this fermentation stage, dried lemongrass and tartaric acid were added. The cherries were then pulped and placed to dry on raised beds until ideal moisture content was achieved. | C14: =+LEN(B14) -> 277 | E14: Finalised
A15: Honey + (Tartaric Acid / Mint) | B15: This coffee was exposed to a dry anaerobic fermentation period of 72 hours with the pulp on. During this fermentation stage, dried mint leaves and tartaric acid were added. The cherries were then pulped and placed to dry on raised beds until ideal moisture content was achieved. | C15: =+LEN(B15) -> 278
A16: Honey + (Tartaric Acid / Ginger) | B16: This coffee was exposed to a dry anaerobic fermentation period of 72 hours with the pulp on. During this fermentation stage,ginger and tartaric acid were added. The cherries were then pulped and placed to dry on raised beds until ideal moisture content was achieved. | C16: =+LEN(B16) -> 266
A17: Honey + (Tartaric Acid / Grape) | B17: This coffee was exposed to a dry anaerobic fermentation period of 72 hours with the pulp on. During this fermentation stage, mashed fresh grapes and tartaric acid were added. The cherries were then pulped and placed to dry on raised beds with mashed fresh grapes placed amongst the coffee until the ideal moisture content was achieved. | C17: =+LEN(B17) -> 335
A18: Honey + (Wine Yeast / Mint) | B18: This coffee was exposed to a dry anaerobic fermentation period of 72 hours with the pulp on. During this fermentation stage, dried mint leaves and wine yeast were added. The cherries were then pulped and placed to dry on raised beds until ideal moisture content was achieved. | C18: =+LEN(B18) -> 275
A19: Honey + (Wine Yeast / Banana Maceration) | B19: This coffee was exposed to a dry anaerobic fermentation period of 72 hours with the pulp on. During this fermentation stage, banana and wine yeast were added. The cherries were then pulped and placed to dry on raised beds until the ideal moisture content was achieved.
A20: Honey + (Wine Yeast / Banana) | B20: This coffee was exposed to a dry anaerobic fermentation period of 72 hours with the pulp on. During this fermentation stage, banana and wine yeast were added. The cherries were then pulped and placed to dry on raised beds until the ideal moisture content was achieved. | C20: =+LEN(B20) -> 268
A21: Honey + (Wine Yeast / Cinnamon) | B21: This coffee was exposed to a dry anaerobic fermentation period of 72 hours with the pulp on. During this fermentation stage, cinnamon sticks and wine yeast were added. The cherries were then pulped and placed to dry on raised beds until the ideal moisture content was achieved. | C21: =+LEN(B21) -> 277
A22: Honey + (Wine Yeast / Lulo) | B22: This coffee was exposed to a dry anaerobic fermentation period of 72 hours with the pulp on. During this fermentation stage, lulo and wine yeast were added. The cherries were then pulped and placed to dry on raised beds until the ideal moisture content was achieved. | C22: =+LEN(B22) -> 266
A23: Honey + (Wine Yeast / Lychee) | B23: This coffee was exposed to a dry anaerobic fermentation period of 72 hours with the pulp on. During this fermentation stage, lychee and wine yeast were added. The cherries were then pulped and placed to dry on raised beds until the ideal moisture content was achieved. | C23: =+LEN(B23) -> 268
A24: Honey + (Wine Yeast / Grape) | B24: This coffee was exposed to a dry anaerobic fermentation period of 72 hours with the pulp on. During this fermentation stage, mashed fresh grapes and wine yeast were added. The cherries were then pulped and placed to dry on raised beds with mashed fresh grapes placed amongst the coffee until the ideal moisture content was achieved. | C24: =+LEN(B24) -> 332
A25: Honey + (Wine Yeast / Orange) | B25: This coffee was exposed to a dry anaerobic fermentation period of 72 hours with the pulp on. During this fermentation stage, ripe oranges and wine yeast were added. The cherries were then pulped and placed to dry on raised beds with ripe oranges placed amongst the coffee until the ideal moisture content was achieved. | C25: =+LEN(B25) -> 318 | E25: Finalised
A26: Honey + (Wine Yeast / Blackberries) | B26: This coffee was exposed to a dry anaerobic fermentation period of 72 hours with the pulp on. During this fermentation stage blackberries and wine yeast were added. The cherries were then pulped and placed to dry on raised beds until the ideal moisture content was achieved.
A27: Honey + (Wine Yeast / Blueberry) | B27: This coffee was exposed to a dry anaerobic fermentation period of 72 hours with the pulp on. During this fermentation stage blueberries and wine yeast were added. The cherries were then pulped and placed to dry on raised beds until the ideal moisture content was achieved.
A28: Honey + (Wine Yeast / Coconut ) | B28: This coffee was exposed to a dry anaerobic fermentation period of 72 hours with the pulp on. During this fermentation stage coconuts and wine yeast were added. The cherries were then pulped and placed to dry on raised beds until the ideal moisture content was achieved.
A29: Honey + (Wine Yeast / Coconut Maceration) | B29: This coffee was exposed to a dry anaerobic fermentation period of 72 hours with the pulp on. During this fermentation stage coconuts and wine yeast were added. The cherries were then pulped and placed to dry on raised beds until the ideal moisture content was achieved.
A30: Honey + (Wine Yeast / Passion Fruit) | B30: This coffee was exposed to a dry anaerobic fermentation period of 72 hours with the pulp on. During this fermentation stage passion fruit pulp and wine yeast were added. The cherries were then pulped and placed to dry on raised beds until the ideal moisture content was achieved. | C30: =+LEN(B30) -> 279
A31: Honey + (Wine Yeast / Green Apple) | B31: This coffee was exposed to a dry anaerobic fermentation period of 72 hours with the pulp on. During this fermentation stage green apple and wine yeast were added. The cherries were then pulped and placed to dry on raised beds until the ideal moisture content was achieved. | C31: =+LEN(B31) -> 272
A32: Honey + (Wine Yeast / Red Fruits) | B32: This coffee was exposed to a dry anaerobic fermentation period of 72 hours with the pulp on. During this fermentation stage ripe red fruits and wine yeast were added. The cherries were then pulped and placed to dry on raised beds with ripe red fruits placed amongst the coffee until the ideal moisture content was achieved. | C32: =+LEN(B32) -> 323
A33: Honey + (Wine Yeast / Dragon Fruit) | B33: This coffee was exposed to a dry anaerobic fermentation period of 72 hours with the pulp on. During this fermentation stage dragon fruit and wine yeast were added. The cherries were then pulped and placed to dry on raised beds until the ideal moisture content was achieved. | C33: =+LEN(B33) -> 273
A34: Honey + (Wine Yeast / Strawberry) | B34: This coffee was exposed to a dry anaerobic fermentation period of 72 hours with the pulp on. During this fermentation stage strawberry and wine yeast were added. The cherries were then pulped and placed to dry on raised beds with ripe strawberry placed amongst the coffee until the ideal moisture content was achieved. | C34: =+LEN(B34) -> 318
A35: Honey+ (Wine Yeast / Coco Peach) | B35: This coffee was exposed to a dry anaerobic fermentation period of 72 hours with the pulp on. During this fermentation stage peaches, coconut and wine yeast were added. The cherries were then pulped and placed to dry on raised beds with peaches placed amongst the coffee until the ideal moisture content was achieved.
A36: Honey+ (Wine Yeast / Peach) | B36: This coffee was exposed to a dry anaerobic fermentation period of 72 hours with the pulp on. During this fermentation stage peaches and wine yeast were added. The cherries were then pulped and placed to dry on raised beds with peaches placed amongst the coffee until the ideal moisture content was achieved. | C36: =+LEN(B36) -> 307
A37: Honey + Green Apple | B37: This coffee was exposed to a dry anaerobic fermentation period of 72 hours with the pulp on. During this fermentation stage, green apples were added. The cherries were then pulped and placed to dry on raised beds until the ideal moisture content was achieved.
A38: Honey + Blackberry | B38: This coffee was exposed to a dry anaerobic fermentation period of 72 hours with the pulp on. During this fermentation stage, ripe blackberries were added. The cherries were then pulped and placed to dry on raised beds until the ideal moisture content was achieved.
A39: Honey + Rose tea | B39: This coffee was exposed to a dry anaerobic fermentation period of 72 hours with the pulp on. During this fermentation stage, smashed roses were added. The cherries were then pulped and placed to dry on raised beds until ideal moisture content was achieved. | C39: =+LEN(B39) -> 256
A40: Honey + Ginger | B40: This coffee was exposed to a dry anaerobic fermentation period of 72 hours with the pulp on. During this fermentation stage,Ginger was added. The cherries were then pulped and placed to dry on raised beds until ideal moisture content was achieved. | C40: =+LEN(B40) -> 247
...

Sheet Farmer
A1: Farm | B1: Altitude | C1: Temperature | D1: Rainfall | E1: Soil | F1: Location | G1: Farmer | H1: Farmer History | I1: text lenght (max 300)
A2: El Cañal | B2: 1650 - 1750 | C2: 16 - 25°C | D2: 1800 - 2000mm | E2: Volcanic Ash | F2: nn, nn | G2: Albeiro Cordoba | H2: Farmer Text---- Farmer Text- -- - Farmer Text ----- Farmer Text --- Farmer Text---- Farmer Text- -- - Farmer Text ----- Farmer Text Farmer Text---- Farmer Text- -- - Farmer Text ----- Farmer Text Farmer Text---- Farmer Text- -- - Farmer Text ----- Farmer Text Farmer Text---- | I2: =+LEN(Farmer!$H2) -> 283
A3: El Despetar | B3: 1900-1950 | C3: 16 - 21°C | D3: 1700-2000 mm | E3: Volcanic Ash | F3: Buesaco, Narino | G3: Albeiro Gomez | H3: Farmer Text---- Farmer Text- -- - Farmer Text ----- Farmer Text --- Farmer Text---- Farmer Text- -- - Farmer Text ----- Farmer Text Farmer Text---- Farmer Text- -- - Farmer Text ----- Farmer Text Farmer Text---- Farmer Text- -- - Farmer Text ----- Farmer Text Farmer Text---- | I3: =+LEN(Farmer!$H3) -> 283
A4: El Deseo | B4: 1600 – 1750 | C4: 14-21°C | D4: 1700-1900 mm | E4: Volcanic Ash | F4: Union, Narino | G4: Albeiro Munoz | H4: Farmer Text---- Farmer Text- -- - Farmer Text ----- Farmer Text --- Farmer Text---- Farmer Text- -- - Farmer Text ----- Farmer Text Farmer Text---- Farmer Text- -- - Farmer Text ----- Farmer Text Farmer Text---- Farmer Text- -- - Farmer Text ----- Farmer Text Farmer Text---- | I4: =+LEN(Farmer!$H4) -> 283
A5: El Remanso | B5: 1850 - 1900 | C5: 16 - 24°C | D5: 1500 – 1600 mm | E5: Volcanic Ash | F5: Planadas, Tolima | G5: Albeiro Roa Ipuz | H5: Farmer Text---- Farmer Text- -- - Farmer Text ----- Farmer Text --- Farmer Text---- Farmer Text- -- - Farmer Text ----- Farmer Text Farmer Text---- Farmer Text- -- - Farmer Text ----- Farmer Text Farmer Text---- Farmer Text- -- - Farmer Text ----- Farmer Text Farmer Text---- | I5: =+LEN(Farmer!$H5) -> 283
A6: Grano de Oro | B6: 1700 – 1750 | C6: 16 - 24°C | D6: 1900 – 2200 mm | E6: Volcanic Ash | F6: Genova, Quindio | G6: Alben Santana | H6: Farmer Text---- Farmer Text- -- - Farmer Text ----- Farmer Text --- Farmer Text---- Farmer Text- -- - Farmer Text ----- Farmer Text Farmer Text---- Farmer Text- -- - Farmer Text ----- Farmer Text Farmer Text---- Farmer Text- -- - Farmer Text ----- Farmer Text Farmer Text---- | I6: =+LEN(Farmer!$H6) -> 283
A7: La Floresta | B7: 1800-1900 | C7: 19 - 25°C | D7: 1700-2100 mm | E7: Volcanic Ash | F7: Gaitania, Tolima | G7: Alberto Ramos | H7: Farmer Text---- Farmer Text- -- - Farmer Text ----- Farmer Text --- Farmer Text---- Farmer Text- -- - Farmer Text ----- Farmer Text Farmer Text---- Farmer Text- -- - Farmer Text ----- Farmer Text Farmer Text---- Farmer Text- -- - Farmer Text ----- Farmer Text Farmer Text---- | I7: =+LEN(Farmer!$H7) -> 283
A8: La Celosa | B8: 1500-1650 | C8: 14 - 28°C | D8: 1600-2000 mm | E8: Volcanic Ash | F8: Acevedo, Huila | G8: Alberto Soto | H8: Farmer Text---- Farmer Text- -- - Farmer Text ----- Farmer Text --- Farmer Text---- Farmer Text- -- - Farmer Text ----- Farmer Text Farmer Text---- Farmer Text- -- - Farmer Text ----- Farmer Text Farmer Text---- Farmer Text- -- - Farmer Text ----- Farmer Text Farmer Text---- | I8: =+LEN(Farmer!$H8) -> 283
A9: La Muralla | B9: 1750-1800 | C9: 16 - 24°C | D9: 1800-2000 mm | E9: Volcanic Ash | F9: Pitalito, Huila | G9: Aldemar Quistal | H9: Farmer Text---- Farmer Text- -- - Farmer Text ----- Farmer Text --- Farmer Text---- Farmer Text- -- - Farmer Text ----- Farmer Text Farmer Text---- Farmer Text- -- - Farmer Text ----- Farmer Text Farmer Text---- Farmer Text- -- - Farmer Text ----- Farmer Text Farmer Text---- | I9: =+LEN(Farmer!$H9) -> 283
A10: La Cumbre | B10: 1750-1800 | C10: 16 - 24°C | D10: 1800-2000 mm | E10: Volcanic Ash | F10: Pitalito,Huila | G10: Alfonso, Molina | H10: Farmer Text---- Farmer Text- -- - Farmer Text ----- Farmer Text --- Farmer Text---- Farmer Text- -- - Farmer Text ----- Farmer Text Farmer Text---- Farmer Text- -- - Farmer Text ----- Farmer Text Farmer Text---- Farmer Text- -- - Farmer Text ----- Farmer Text Farmer Text---- | I10: =+LEN(Farmer!$H10) -> 283
A11: Las Peñas | B11: 1700-1800 | C11: 13 - 24°C | D11: 1900-2200 mm | E11: Volcanic Ash | F11: Manta, Cundinamarca | G11: Alirio | H11: Farmer Text---- Farmer Text- -- - Farmer Text ----- Farmer Text --- Farmer Text---- Farmer Text- -- - Farmer Text ----- Farmer Text Farmer Text---- Farmer Text- -- - Farmer Text ----- Farmer Text Farmer Text---- Farmer Text- -- - Farmer Text ----- Farmer Text Farmer Text---- | I11: =+LEN(Farmer!$H11) -> 283
A12: La Mariela | B12: 1900-1950 | C12: 15-24°C | D12: 1900-2200mm | E12: Volcanic Ash | F12: Genova, Quindio | G12: Alirio Buitrago | H12: Farmer Text---- Farmer Text- -- - Farmer Text ----- Farmer Text --- Farmer Text---- Farmer Text- -- - Farmer Text ----- Farmer Text Farmer Text---- Farmer Text- -- - Farmer Text ----- Farmer Text Farmer Text---- Farmer Text- -- - Farmer Text ----- Farmer Text Farmer Text---- | I12: =+LEN(Farmer!$H12) -> 283
A13: El Manantial | B13: 1740 - 1800 | C13: 19 - 26°C | D13: 1700-2200 mm | E13: Volcanic Ash | F13: Gaitania, Tolima | G13: Alirio Pecupaque | H13: Farmer Text---- Farmer Text- -- - Farmer Text ----- Farmer Text --- Farmer Text---- Farmer Text- -- - Farmer Text ----- Farmer Text Farmer Text---- Farmer Text- -- - Farmer Text ----- Farmer Text Farmer Text---- Farmer Text- -- - Farmer Text ----- Farmer Text Farmer Text---- | I13: =+LEN(Farmer!$H13) -> 283
B14: 1750-1800 | C14: 19 - 25°C | D14: 1700-2200 mm | E14: Volcanic Ash | F14: Gaitania, Tolima | G14: Alirio Pecupaque | H14: Farmer Text---- Farmer Text- -- - Farmer Text ----- Farmer Text --- Farmer Text---- Farmer Text- -- - Farmer Text ----- Farmer Text Farmer Text---- Farmer Text- -- - Farmer Text ----- Farmer Text Farmer Text---- Farmer Text- -- - Farmer Text ----- Farmer Text Farmer Text---- | I14: =+LEN(Farmer!$H14) -> 283
A15: El Cedro | B15: 1400-1450 | C15: 17 - 26°C | D15: 1600 – 1800 mm | E15: Volcanic Ash | F15: Acevedo, Huila | G15: Alirio Rodriguez | H15: Farmer Text---- Farmer Text- -- - Farmer Text ----- Farmer Text --- Farmer Text---- Farmer Text- -- - Farmer Text ----- Farmer Text Farmer Text---- Farmer Text- -- - Farmer Text ----- Farmer Text Farmer Text---- Farmer Text- -- - Farmer Text ----- Farmer Text Farmer Text---- | I15: =+LEN(Farmer!$H15) -> 283
A16: La Villa Hermosa | B16: 1700-1900 | C16: 18 - 24°C | D16: 1700-2000 mm | E16: Volcanic Ash | F16: San Adolfo, Huila | G16: Alirio Vargas | H16: Farmer Text---- Farmer Text- -- - Farmer Text ----- Farmer Text --- Farmer Text---- Farmer Text- -- - Farmer Text ----- Farmer Text Farmer Text---- Farmer Text- -- - Farmer Text ----- Farmer Text Farmer Text---- Farmer Text- -- - Farmer Text ----- Farmer Text Farmer Text---- | I16: =+LEN(Farmer!$H16) -> 283
A17: Guacanas | B17: 1750 - 1800 | C17: 12 - 27°C | D17: 1900-2000mm | E17: Volcanic Ash | F17: San Adolfo, Huila | G17: Andres Guaca | H17: Farmer Text---- Farmer Text- -- - Farmer Text ----- Farmer Text --- Farmer Text---- Farmer Text- -- - Farmer Text ----- Farmer Text Farmer Text---- Farmer Text- -- - Farmer Text ----- Farmer Text Farmer Text---- Farmer Text- -- - Farmer Text ----- Farmer Text Farmer Text---- | I17: =+LEN(Farmer!$H17) -> 283
A18: Manantiales del Frontino | B18: 1800 – 1900 | C18: 18-35°C | D18: 1700 – 1900 mm | E18: Volcanic Ash | F18: Caicedonia, Valle del Cauca | G18: Andres Londono | H18: Farmer Text---- Farmer Text- -- - Farmer Text ----- Farmer Text --- Farmer Text---- Farmer Text- -- - Farmer Text ----- Farmer Text Farmer Text---- Farmer Text- -- - Farmer Text ----- Farmer Text Farmer Text---- Farmer Text- -- - Farmer Text ----- Farmer Text Farmer Text---- | I18: =+LEN(Farmer!$H18) -> 283
A19: El Centro | B19: 1750 - 1800 | C19: 14 - 26°C | D19: 1900-2100 mm | E19: Volcanic Ash | F19: Genova, Quindio | G19: Andres Mauricio Ramirez | H19: Farmer Text---- Farmer Text- -- - Farmer Text ----- Farmer Text --- Farmer Text---- Farmer Text- -- - Farmer Text ----- Farmer Text Farmer Text---- Farmer Text- -- - Farmer Text ----- Farmer Text Farmer Text---- Farmer Text- -- - Farmer Text ----- Farmer Text Farmer Text---- | I19: =+LEN(Farmer!$H19) -> 283
A20: El Laguito | B20: 1500 - 1600 | C20: 14 - 28°C | D20: 2000-2200 mm | E20: Volcanic ash | F20: Calarca, Quindio | G20: Andres Ramirez | H20: Farmer Text---- Farmer Text- -- - Farmer Text ----- Farmer Text --- Farmer Text---- Farmer Text- -- - Farmer Text ----- Farmer Text Farmer Text---- Farmer Text- -- - Farmer Text ----- Farmer Text Farmer Text---- Farmer Text- -- - Farmer Text ----- Farmer Text Farmer Text---- | I20: =+LEN(Farmer!$H20) -> 283
A21: El Laguito | B21: 1500 - 1600 | C21: 14 - 28°C | D21: 2000 - 2200 mm | E21: Volcanic Ashes | F21: Calarca, Quindio | G21: Andres Ramirez | H21: Farmer Text---- Farmer Text- -- - Farmer Text ----- Farmer Text --- Farmer Text---- Farmer Text- -- - Farmer Text ----- Farmer Text Farmer Text---- Farmer Text- -- - Farmer Text ----- Farmer Text Farmer Text---- Farmer Text- -- - Farmer Text ----- Farmer Text Farmer Text---- | I21: =+LEN(Farmer!$H21) -> 283
A22: El Palmichal | B22: 1500 - 1600 | C22: 14 - 26°C | D22: 1900-2100 mm | E22: Volcanic Ash | F22: Genova, Quindio | G22: Atilano Giraldo | H22: Farmer Text---- Farmer Text- -- - Farmer Text ----- Farmer Text --- Farmer Text---- Farmer Text- -- - Farmer Text ----- Farmer Text Farmer Text---- Farmer Text- -- - Farmer Text ----- Farmer Text Farmer Text---- Farmer Text- -- - Farmer Text ----- Farmer Text Farmer Text---- | I22: =+LEN(Farmer!$H22) -> 283
A23: Paraiso | B23: 1700 - 1750 | C23: 18 - 24°C | D23: 1900 - 2100 mm | E23: Clay loam | F23: Timana, Huila | G23: Anselmo Trujillo | H23: Farmer Text---- Farmer Text- -- - Farmer Text ----- Farmer Text --- Farmer Text---- Farmer Text- -- - Farmer Text ----- Farmer Text Farmer Text---- Farmer Text- -- - Farmer Text ----- Farmer Text Farmer Text---- Farmer Text- -- - Farmer Text ----- Farmer Text Farmer Text---- | I23: =+LEN(Farmer!$H23) -> 283
A24: La Esperanza | B24: 1900 - 2000 | C24: 16 - 21°C | D24: 1500 – 1800 mm | E24: Volcanic Ash | F24: Planadas, Tolima. | G24: Argenis Muñoz Cuellar | H24: Farmer Text---- Farmer Text- -- - Farmer Text ----- Farmer Text --- Farmer Text---- Farmer Text- -- - Farmer Text ----- Farmer Text Farmer Text---- Farmer Text- -- - Farmer Text ----- Farmer Text Farmer Text---- Farmer Text- -- - Farmer Text ----- Farmer Text Farmer Text---- | I24: =+LEN(Farmer!$H24) -> 283
A25: Las Nubes | B25: 2000 – 2100 | C25: 12 - 22°C | D25: 1900 – 2200 mm | E25: Volcanic Ash | F25: Genova, Quindio | G25: Arles Ramirez | H25: Farmer Text---- Farmer Text- -- - Farmer Text ----- Farmer Text --- Farmer Text---- Farmer Text- -- - Farmer Text ----- Farmer Text Farmer Text---- Farmer Text- -- - Farmer Text ----- Farmer Text Farmer Text---- Farmer Text- -- - Farmer Text ----- Farmer Text Farmer Text---- | I25: =+LEN(Farmer!$H25) -> 283
A26: Villa Sebastian | B26: 1700-1750 | C26: 16 - 25°C | D26: 1600-2000 mm | E26: Clay loam | F26: Cartago, Nariño | G26: Camila Gomez | H26: Farmer Text---- Farmer Text- -- - Farmer Text ----- Farmer Text --- Farmer Text---- Farmer Text- -- - Farmer Text ----- Farmer Text Farmer Text---- Farmer Text- -- - Farmer Text ----- Farmer Text Farmer Text---- Farmer Text- -- - Farmer Text ----- Farmer Text Farmer Text---- | I26: =+LEN(Farmer!$H26) -> 283
... A39: La Divisa | B39: 1600 -2000 | C39: 16 - 24 °C | D39: 1900-2200mm | E39: Volcanic Ash | F39: Buenavista, Quindio | G39: Diofanor Ruiz | H39: Farmer Text---- Farmer Text- -- - Farmer Text ----- Farmer Text --- Farmer Text---- Farmer Text- -- - Farmer Text ----- Farmer Text Farmer Text---- Farmer Text- -- - Farmer Text ----- Farmer Text Farmer Text---- Farmer Text- -- - Farmer Text ----- Farmer Text Farmer Text---- | I39: =+LEN(Farmer!$H39) -> 283
A40: Buena Vista | B40: 1600 -1700 | C40: 16 - 24 °C | D40: 1900-2200mm | E40: Volcanic Ash | F40: Buenavista, Quindio | G40: Diofanor Ruiz
A41: Las Flores | B41: 1700-2000 | C41: 17 - 26°C | D41: 1600 - 2000 mm | E41: Clay loam | F41: San Isidro, Huila | G41: Edilberto Vergara | H41: Farmer Text---- Farmer Text- -- - Farmer Text ----- Farmer Text --- Farmer Text---- Farmer Text- -- - Farmer Text ----- Farmer Text Farmer Text---- Farmer Text- -- - Farmer Text ----- Farmer Text Farmer Text---- Farmer Text- -- - Farmer Text ----- Farmer Text Farmer Text---- | I41: =+LEN(Farmer!$H41) -> 283
A42: La Pola | B42: 1400 - 1450 | C42: 17 - 26°C | D42: 1800 - 2100mm | E42: Volcanic Ash | F42: Armenia, Quindio | G42: Eduardo Posada | H42: Farmer Text---- Farmer Text- -- - Farmer Text ----- Farmer Text --- Farmer Text---- Farmer Text- -- - Farmer Text ----- Farmer Text Farmer Text---- Farmer Text- -- - Farmer Text ----- Farmer Text Farmer Text---- Farmer Text- -- - Farmer Text ----- Farmer Text Farmer Text---- | I42: =+LEN(Farmer!$H42) -> 283
A43: La Albania | B43: 1680 -1750 | C43: 14 - 26°C | D43: 1900 - 2100 mm | E43: Volcanic Ash | F43: Planadas, Tolima | G43: Ely Hueje | H43: Farmer Text---- Farmer Text- -- - Farmer Text ----- Farmer Text --- Farmer Text---- Farmer Text- -- - Farmer Text ----- Farmer Text Farmer Text---- Farmer Text- -- - Farmer Text ----- Farmer Text Farmer Text---- Farmer Text- -- - Farmer Text ----- Farmer Text Farmer Text---- | I43: =+LEN(Farmer!$H43) -> 283
A44: El Edin | B44: 1700-1800 | C44: 18 - 23°C | D44: 1800 - 2200mm | E44: Clay loam | F44: Bruselas, Huila | G44: Eriberto Gomez | H44: Farmer Text---- Farmer Text- -- - Farmer Text ----- Farmer Text --- Farmer Text---- Farmer Text- -- - Farmer Text ----- Farmer Text Farmer Text---- Farmer Text- -- - Farmer Text ----- Farmer Text Farmer Text---- Farmer Text- -- - Farmer Text ----- Farmer Text Farmer Text---- | I44: =+LEN(Farmer!$H44) -> 283
A45: La Perla | B45: 1630 - 1800 | C45: 12 - 22°C | D45: 1700 - 2200 mm | E45: Volcanis Ashes, Clay Loam | F45: Gaitania, Tolima | G45: Ever Silva | H45: Farmer Text---- Farmer Text- -- - Farmer Text ----- Farmer Text --- Farmer Text---- Farmer Text- -- - Farmer Text ----- Farmer Text Farmer Text---- Farmer Text- -- - Farmer Text ----- Farmer Text Farmer Text---- Farmer Text- -- - Farmer Text ----- Farmer Text Farmer Text---- | I45: =+LEN(Farmer!$H45) -> 283
A46: Jardines del Encanto | B46: 1750 - 2150 | C46: 12 - 28°C | D46: 1900-2200 mm | E46: Volcanic Ash | F46: Pijao, Quindio | G46: Felipe Arcila | H46: Farmer Text---- Farmer Text- -- - Farmer Text ----- Farmer Text --- Farmer Text---- Farmer Text- -- - Farmer Text ----- Farmer Text Farmer Text---- Farmer Text- -- - Farmer Text ----- Farmer Text Farmer Text---- Farmer Text- -- - Farmer Text ----- Farmer Text Farmer Text---- | I46: =+LEN(Farmer!$H46) -> 283
A47: Jardines Del Eden | B47: 1700-1900 | C47: 12 - 28°C | D47: 1900-2200 mm | E47: Volcanic Ash | F47: Pijao, Quindio | G47: Felipe Arcila | H47: Farmer Text---- Farmer Text- -- - Farmer Text ----- Farmer Text --- Farmer Text---- Farmer Text- -- - Farmer Text ----- Farmer Text Farmer Text---- Farmer Text- -- - Farmer Text ----- Farmer Text Farmer Text---- Farmer Text- -- - Farmer Text ----- Farmer Text Farmer Text---- | I47: =+LEN(Farmer!$H47) -> 283
A48: El Rubi | B48: 1700 - 1900 | C48: 12 - 28°C | D48: 1900-2000 mm | E48: Volcanic Ash | F48: Palestina , Huila | G48: Felipe Henao | H48: Farmer Text---- Farmer Text- -- - Farmer Text ----- Farmer Text --- Farmer Text---- Farmer Text- -- - Farmer Text ----- Farmer Text Farmer Text---- Farmer Text- -- - Farmer Text ----- Farmer Text Farmer Text---- Farmer Text- -- - Farmer Text ----- Farmer Text Farmer Text---- | I48: =+LEN(Farmer!$H48) -> 283
A49: La America | B49: 1855 - 1900 | C49: 19 - 25°C | D49: 1700 - 2200 mm | E49: Volcanic Ash | F49: Planadas, Tolima | G49: Felipe Perez | H49: Farmer Text---- Farmer Text- -- - Farmer Text ----- Farmer Text --- Farmer Text---- Farmer Text- -- - Farmer Text ----- Farmer Text Farmer Text---- Farmer Text- -- - Farmer Text ----- Farmer Text Farmer Text---- Farmer Text- -- - Farmer Text ----- Farmer Text Farmer Text---- | I49: =+LEN(Farmer!$H49) -> 283
A50: Los Olivos | B50: 1830 - 1900 | C50: 19 - 25°C | D50: 1700-2200 mm | E50: Volcanic Ash | F50: Gaitania, Tolima | G50: Floralba Apio | H50: Farmer Text---- Farmer Text- -- - Farmer Text ----- Farmer Text --- Farmer Text---- Farmer Text- -- - Farmer Text ----- Farmer Text Farmer Text---- Farmer Text- -- - Farmer Text ----- Farmer Text Farmer Text---- Farmer Text- -- - Farmer Text ----- Farmer Text Farmer Text---- | I50: =+LEN(Farmer!$H50) -> 283
A51: El Pastal | B51: 1800 – 1850 | C51: 16 – 24°C | D51: 1900 – 2200 mm | E51: Volcanic Ash | F51: Genova, Quindio | G51: Francisco Florez | H51: Farmer Text---- Farmer Text- -- - Farmer Text ----- Farmer Text --- Farmer Text---- Farmer Text- -- - Farmer Text ----- Farmer Text Farmer Text---- Farmer Text- -- - Farmer Text ----- Farmer Text Farmer Text---- Farmer Text- -- - Farmer Text ----- Farmer Text Farmer Text---- | I51: =+LEN(Farmer!$H51) -> 283
A52: Loma Linda | B52: 1850 -1900 | C52: 13 - 25°C | D52: 1500 - 1800 mm | E52: Volcanic Ash | F52: Buesaco, Nariño | G52: Franco Chavez | H52: Farmer Text---- Farmer Text- -- - Farmer Text ----- Farmer Text --- Farmer Text---- Farmer Text- -- - Farmer Text ----- Farmer Text Farmer Text---- Farmer Text- -- - Farmer Text ----- Farmer Text Farmer Text---- Farmer Text- -- - Farmer Text ----- Farmer Text Farmer Text---- | I52: =+LEN(Farmer!$H52) -> 283
...
